2024-02-14 13:28:47,134 [DEBUG] py4...: Calling cytoscape_ping()
2024-02-14 13:28:47,134 [DEBUG] py4...: ǀCalling cytoscape_version_info(base_url='http://127.0.0.1:1234/v1')
2024-02-14 13:28:47,134 [DEBUG] py4...: ǀǀCalling cyrest_get('version', base_url='http://127.0.0.1:1234/v1')
2024-02-14 13:28:47,134 [DEBUG] py4...: Attempting to direct connect to Cytoscape on http://127.0.0.1:1234/v1
2024-02-14 13:28:49,185 [DEBUG] py4...: Attempting to connect to remote Cytoscape because of error HTTPConnectionPool(host='127.0.0.1', port=1234): Max retries exceeded with url: /v1 (Caused by NewConnectionError('<urllib3.connection.HTTPConnection object at 0x0000022FE85E5EA0>: Failed to establish a new connection: [WinError 10061] 由于目标计算机积极拒绝，无法连接。'))
2024-02-14 13:28:49,188 [DEBUG] py4...: ǀǀHTTP GET(http://127.0.0.1:1234/v1)
2024-02-14 13:28:51,790 [DEBUG] py4...: Error initially contacting Jupyter-bridge: Error posting to Jupyter-bridge: Channel None:request contains unprocessed message
2024-02-14 13:28:51,790 [DEBUG] py4...: ǀǀ'cyrest_get' exception RequestException('Cannot find local or remote Cytoscape. Start Cytoscape and then proceed.')
2024-02-14 13:28:51,791 [DEBUG] py4...: ǀ'cytoscape_version_info' exception RequestException('Cannot find local or remote Cytoscape. Start Cytoscape and then proceed.')
2024-02-14 13:28:51,791 [DEBUG] py4...: 'cytoscape_ping' exception RequestException('Cannot find local or remote Cytoscape. Start Cytoscape and then proceed.')
2024-02-14 13:28:51,791 [DEBUG] py4...: --------------------
2024-02-14 13:32:58,266 [DEBUG] py4...: Calling cytoscape_ping()
2024-02-14 13:32:58,266 [DEBUG] py4...: ǀCalling cytoscape_version_info(base_url='http://127.0.0.1:1234/v1')
2024-02-14 13:32:58,266 [DEBUG] py4...: ǀǀCalling cyrest_get('version', base_url='http://127.0.0.1:1234/v1')
2024-02-14 13:32:58,266 [DEBUG] py4...: Attempting to direct connect to Cytoscape on http://127.0.0.1:1234/v1
2024-02-14 13:33:03,207 [DEBUG] py4...: Calling cytoscape_ping()
2024-02-14 13:33:03,208 [DEBUG] py4...: ǀCalling cytoscape_version_info(base_url='http://127.0.0.1:1234/v1')
2024-02-14 13:33:03,208 [DEBUG] py4...: ǀǀCalling cyrest_get('version', base_url='http://127.0.0.1:1234/v1')
2024-02-14 13:33:03,208 [DEBUG] py4...: Attempting to direct connect to Cytoscape on http://127.0.0.1:1234/v1
2024-02-14 13:33:05,250 [DEBUG] py4...: Attempting to connect to remote Cytoscape because of error HTTPConnectionPool(host='127.0.0.1', port=1234): Max retries exceeded with url: /v1 (Caused by NewConnectionError('<urllib3.connection.HTTPConnection object at 0x000001FD04965180>: Failed to establish a new connection: [WinError 10061] 由于目标计算机积极拒绝，无法连接。'))
2024-02-14 13:33:05,250 [DEBUG] py4...: ǀǀHTTP GET(http://127.0.0.1:1234/v1)
2024-02-14 13:33:07,114 [DEBUG] py4...: Error initially contacting Jupyter-bridge: Error posting to Jupyter-bridge: Channel None:request contains unprocessed message
2024-02-14 13:33:07,114 [DEBUG] py4...: ǀǀ'cyrest_get' exception RequestException('Cannot find local or remote Cytoscape. Start Cytoscape and then proceed.')
2024-02-14 13:33:07,114 [DEBUG] py4...: ǀ'cytoscape_version_info' exception RequestException('Cannot find local or remote Cytoscape. Start Cytoscape and then proceed.')
2024-02-14 13:33:07,115 [DEBUG] py4...: 'cytoscape_ping' exception RequestException('Cannot find local or remote Cytoscape. Start Cytoscape and then proceed.')
2024-02-14 13:33:07,115 [DEBUG] py4...: --------------------
2024-02-14 13:38:31,549 [DEBUG] py4...: Calling cytoscape_ping()
2024-02-14 13:38:31,550 [DEBUG] py4...: ǀCalling cytoscape_version_info(base_url='http://127.0.0.1:1234/v1')
2024-02-14 13:38:31,550 [DEBUG] py4...: ǀǀCalling cyrest_get('version', base_url='http://127.0.0.1:1234/v1')
2024-02-14 13:38:31,550 [DEBUG] py4...: Attempting to direct connect to Cytoscape on http://127.0.0.1:1234/v1
2024-02-14 13:38:33,589 [DEBUG] py4...: Attempting to connect to remote Cytoscape because of error HTTPConnectionPool(host='127.0.0.1', port=1234): Max retries exceeded with url: /v1 (Caused by NewConnectionError('<urllib3.connection.HTTPConnection object at 0x000001553591B7F0>: Failed to establish a new connection: [WinError 10061] 由于目标计算机积极拒绝，无法连接。'))
2024-02-14 13:38:33,589 [DEBUG] py4...: ǀǀHTTP GET(http://127.0.0.1:1234/v1)
2024-02-14 13:38:35,797 [DEBUG] py4...: Error initially contacting Jupyter-bridge: Error posting to Jupyter-bridge: Channel None:request contains unprocessed message
2024-02-14 13:38:35,797 [DEBUG] py4...: ǀǀ'cyrest_get' exception RequestException('Cannot find local or remote Cytoscape. Start Cytoscape and then proceed.')
2024-02-14 13:38:35,797 [DEBUG] py4...: ǀ'cytoscape_version_info' exception RequestException('Cannot find local or remote Cytoscape. Start Cytoscape and then proceed.')
2024-02-14 13:38:35,797 [DEBUG] py4...: 'cytoscape_ping' exception RequestException('Cannot find local or remote Cytoscape. Start Cytoscape and then proceed.')
2024-02-14 13:38:35,797 [DEBUG] py4...: --------------------
2024-02-14 13:48:32,634 [DEBUG] py4...: Calling cytoscape_ping()
2024-02-14 13:48:32,635 [DEBUG] py4...: ǀCalling cytoscape_version_info(base_url='http://127.0.0.1:1234/v1')
2024-02-14 13:48:32,635 [DEBUG] py4...: ǀǀCalling cyrest_get('version', base_url='http://127.0.0.1:1234/v1')
2024-02-14 13:48:32,635 [DEBUG] py4...: Attempting to direct connect to Cytoscape on http://127.0.0.1:1234/v1
2024-02-14 13:48:34,698 [DEBUG] py4...: Attempting to connect to remote Cytoscape because of error HTTPConnectionPool(host='127.0.0.1', port=1234): Max retries exceeded with url: /v1 (Caused by NewConnectionError('<urllib3.connection.HTTPConnection object at 0x000002464AF2B7F0>: Failed to establish a new connection: [WinError 10061] 由于目标计算机积极拒绝，无法连接。'))
2024-02-14 13:48:34,698 [DEBUG] py4...: ǀǀHTTP GET(http://127.0.0.1:1234/v1)
2024-02-14 13:48:35,901 [DEBUG] py4...: Error initially contacting Jupyter-bridge: Error posting to Jupyter-bridge: Channel None:request contains unprocessed message
2024-02-14 13:48:35,901 [DEBUG] py4...: ǀǀ'cyrest_get' exception RequestException('Cannot find local or remote Cytoscape. Start Cytoscape and then proceed.')
2024-02-14 13:48:35,901 [DEBUG] py4...: ǀ'cytoscape_version_info' exception RequestException('Cannot find local or remote Cytoscape. Start Cytoscape and then proceed.')
2024-02-14 13:48:35,902 [DEBUG] py4...: 'cytoscape_ping' exception RequestException('Cannot find local or remote Cytoscape. Start Cytoscape and then proceed.')
2024-02-14 13:48:35,902 [DEBUG] py4...: --------------------
2024-02-14 13:49:34,915 [DEBUG] py4...: Calling cytoscape_ping()
2024-02-14 13:49:34,915 [DEBUG] py4...: ǀCalling cytoscape_version_info(base_url='http://127.0.0.1:1234/v1')
2024-02-14 13:49:34,915 [DEBUG] py4...: ǀǀCalling cyrest_get('version', base_url='http://127.0.0.1:1234/v1')
2024-02-14 13:49:34,915 [DEBUG] py4...: Attempting to direct connect to Cytoscape on http://127.0.0.1:1234/v1
2024-02-14 13:49:35,070 [DEBUG] py4...: Detected py4cytoscape running on Cytoscape workstation
2024-02-14 13:49:35,071 [DEBUG] py4...: ǀǀHTTP GET(http://127.0.0.1:1234/v1/version)
2024-02-14 13:49:35,081 [DEBUG] py4...: ǀǀOK[200], content: {"apiVersion":"v1","cytoscapeVersion":"3.10.1"}
2024-02-14 13:49:35,081 [DEBUG] py4...: ǀǀReturning 'cyrest_get': {'apiVersion': 'v1', 'cytoscapeVersion': '3.10.1'}
2024-02-14 13:49:35,082 [DEBUG] py4...: ǀReturning 'cytoscape_version_info': {'apiVersion': 'v1', 'cytoscapeVersion': '3.10.1', 'automationAPIVersion': '1.9.0', 'py4cytoscapeVersion': '1.9.0'}
2024-02-14 13:49:35,082 [DEBUG] py4...: Returning 'cytoscape_ping': 'You are connected to Cytoscape!'
2024-02-14 13:49:35,082 [DEBUG] py4...: --------------------
2024-02-14 13:49:35,082 [DEBUG] py4...: Calling delete_all_networks()
2024-02-14 13:49:35,082 [DEBUG] py4...: ǀCalling cyrest_delete('networks', base_url='http://127.0.0.1:1234/v1', require_json=False)
2024-02-14 13:49:35,082 [DEBUG] py4...: ǀHTTP DELETE(http://127.0.0.1:1234/v1/networks)
2024-02-14 13:49:35,092 [DEBUG] py4...: ǀOK[200], content: 
2024-02-14 13:49:35,092 [DEBUG] py4...: ǀReturning 'cyrest_delete': ''
2024-02-14 13:49:35,092 [DEBUG] py4...: Returning 'delete_all_networks': ''
2024-02-14 13:49:35,092 [DEBUG] py4...: --------------------
2024-02-14 13:49:35,092 [DEBUG] py4...: Calling create_network_from_data_frames([{'data': {'id': 'a'}}, {'data': {'id': 'b'}}, {'data': {'id': 'c'}}], [{'data': {'source': 'a', 'target': 'b'}}, {'data': {'source': 'a', 'target': 'c'}}, {'data': {'source': 'b', 'target': 'c'}}], title='My Graph')
2024-02-14 13:49:35,093 [DEBUG] py4...: 'create_network_from_data_frames' exception TypeError('list indices must be integers or slices, not str')
2024-02-14 13:49:35,093 [DEBUG] py4...: --------------------
2024-02-14 13:51:26,866 [DEBUG] py4...: Calling cytoscape_ping()
2024-02-14 13:51:26,866 [DEBUG] py4...: ǀCalling cytoscape_version_info(base_url='http://127.0.0.1:1234/v1')
2024-02-14 13:51:26,866 [DEBUG] py4...: ǀǀCalling cyrest_get('version', base_url='http://127.0.0.1:1234/v1')
2024-02-14 13:51:26,867 [DEBUG] py4...: Attempting to direct connect to Cytoscape on http://127.0.0.1:1234/v1
2024-02-14 13:51:28,388 [DEBUG] py4...: ǀǀǀCalling cytoscape_ping()
2024-02-14 13:51:28,388 [DEBUG] py4...: ǀǀǀǀCalling cytoscape_version_info(base_url='http://127.0.0.1:1234/v1')
2024-02-14 13:51:28,388 [DEBUG] py4...: ǀǀǀǀǀCalling cyrest_get('version', base_url='http://127.0.0.1:1234/v1')
2024-02-14 13:51:28,388 [DEBUG] py4...: Attempting to direct connect to Cytoscape on http://127.0.0.1:1234/v1
2024-02-14 13:51:28,818 [DEBUG] py4...: ǀǀǀǀǀǀCalling cytoscape_ping()
2024-02-14 13:51:28,818 [DEBUG] py4...: ǀǀǀǀǀǀǀCalling cytoscape_version_info(base_url='http://127.0.0.1:1234/v1')
2024-02-14 13:51:28,819 [DEBUG] py4...: ǀǀǀǀǀǀǀǀCalling cyrest_get('version', base_url='http://127.0.0.1:1234/v1')
2024-02-14 13:51:28,819 [DEBUG] py4...: Attempting to direct connect to Cytoscape on http://127.0.0.1:1234/v1
2024-02-14 13:51:28,900 [DEBUG] py4...: Attempting to connect to remote Cytoscape because of error HTTPConnectionPool(host='127.0.0.1', port=1234): Max retries exceeded with url: /v1 (Caused by NewConnectionError('<urllib3.connection.HTTPConnection object at 0x0000018A3A94B910>: Failed to establish a new connection: [WinError 10061] 由于目标计算机积极拒绝，无法连接。'))
2024-02-14 13:51:28,900 [DEBUG] py4...: ǀǀǀǀǀǀǀǀHTTP GET(http://127.0.0.1:1234/v1)
2024-02-14 13:51:29,176 [DEBUG] py4...: ǀǀǀǀǀǀǀǀǀCalling cytoscape_ping()
2024-02-14 13:51:29,176 [DEBUG] py4...: ǀǀǀǀǀǀǀǀǀǀCalling cytoscape_version_info(base_url='http://127.0.0.1:1234/v1')
2024-02-14 13:51:29,176 [DEBUG] py4...: ǀǀǀǀǀǀǀǀǀǀǀCalling cyrest_get('version', base_url='http://127.0.0.1:1234/v1')
2024-02-14 13:51:29,176 [DEBUG] py4...: Attempting to direct connect to Cytoscape on http://127.0.0.1:1234/v1
2024-02-14 13:51:29,593 [DEBUG] py4...: ǀǀǀǀǀǀǀǀǀǀǀǀCalling cytoscape_ping()
2024-02-14 13:51:29,594 [DEBUG] py4...: ǀǀǀǀǀǀǀǀǀǀǀǀǀCalling cytoscape_version_info(base_url='http://127.0.0.1:1234/v1')
2024-02-14 13:51:29,594 [DEBUG] py4...: ǀǀǀǀǀǀǀǀǀǀǀǀǀǀCalling cyrest_get('version', base_url='http://127.0.0.1:1234/v1')
2024-02-14 13:51:29,594 [DEBUG] py4...: Attempting to direct connect to Cytoscape on http://127.0.0.1:1234/v1
2024-02-14 13:51:30,148 [DEBUG] py4...: Error initially contacting Jupyter-bridge: Error posting to Jupyter-bridge: Channel None:request contains unprocessed message
2024-02-14 13:51:30,148 [DEBUG] py4...: ǀǀǀǀǀǀǀǀǀǀǀǀǀǀ'cyrest_get' exception RequestException('Cannot find local or remote Cytoscape. Start Cytoscape and then proceed.')
2024-02-14 13:51:30,148 [DEBUG] py4...: ǀǀǀǀǀǀǀǀǀǀǀǀǀ'cytoscape_version_info' exception RequestException('Cannot find local or remote Cytoscape. Start Cytoscape and then proceed.')
2024-02-14 13:51:30,148 [DEBUG] py4...: ǀǀǀǀǀǀǀǀǀǀǀǀ'cytoscape_ping' exception RequestException('Cannot find local or remote Cytoscape. Start Cytoscape and then proceed.')
2024-02-14 13:51:30,422 [DEBUG] py4...: ǀǀǀǀǀǀǀǀǀǀǀǀCalling cytoscape_ping()
2024-02-14 13:51:30,423 [DEBUG] py4...: ǀǀǀǀǀǀǀǀǀǀǀǀǀCalling cytoscape_version_info(base_url='http://127.0.0.1:1234/v1')
2024-02-14 13:51:30,423 [DEBUG] py4...: ǀǀǀǀǀǀǀǀǀǀǀǀǀǀCalling cyrest_get('version', base_url='http://127.0.0.1:1234/v1')
2024-02-14 13:51:30,423 [DEBUG] py4...: Attempting to direct connect to Cytoscape on http://127.0.0.1:1234/v1
2024-02-14 13:51:30,440 [DEBUG] py4...: Attempting to connect to remote Cytoscape because of error HTTPConnectionPool(host='127.0.0.1', port=1234): Max retries exceeded with url: /v1 (Caused by NewConnectionError('<urllib3.connection.HTTPConnection object at 0x0000018A3A949ED0>: Failed to establish a new connection: [WinError 10061] 由于目标计算机积极拒绝，无法连接。'))
2024-02-14 13:51:30,440 [DEBUG] py4...: ǀǀǀǀǀǀǀǀǀǀǀǀǀǀHTTP GET(http://127.0.0.1:1234/v1)
2024-02-14 13:51:30,874 [DEBUG] py4...: Attempting to connect to remote Cytoscape because of error HTTPConnectionPool(host='127.0.0.1', port=1234): Max retries exceeded with url: /v1 (Caused by NewConnectionError('<urllib3.connection.HTTPConnection object at 0x0000018A3A9B4220>: Failed to establish a new connection: [WinError 10061] 由于目标计算机积极拒绝，无法连接。'))
2024-02-14 13:51:30,874 [DEBUG] py4...: ǀǀǀǀǀǀǀǀǀǀǀǀǀǀHTTP GET(http://127.0.0.1:1234/v1)
2024-02-14 13:51:31,232 [DEBUG] py4...: Attempting to connect to remote Cytoscape because of error HTTPConnectionPool(host='127.0.0.1', port=1234): Max retries exceeded with url: /v1 (Caused by NewConnectionError('<urllib3.connection.HTTPConnection object at 0x0000018A3A9B5F00>: Failed to establish a new connection: [WinError 10061] 由于目标计算机积极拒绝，无法连接。'))
2024-02-14 13:51:31,233 [DEBUG] py4...: ǀǀǀǀǀǀǀǀǀǀǀǀǀǀHTTP GET(http://127.0.0.1:1234/v1)
2024-02-14 13:51:31,633 [DEBUG] py4...: Attempting to connect to remote Cytoscape because of error HTTPConnectionPool(host='127.0.0.1', port=1234): Max retries exceeded with url: /v1 (Caused by NewConnectionError('<urllib3.connection.HTTPConnection object at 0x0000018A3A9B6EC0>: Failed to establish a new connection: [WinError 10061] 由于目标计算机积极拒绝，无法连接。'))
2024-02-14 13:51:31,633 [DEBUG] py4...: ǀǀǀǀǀǀǀǀǀǀǀǀǀǀHTTP GET(http://127.0.0.1:1234/v1)
2024-02-14 13:51:31,681 [DEBUG] py4...: Error initially contacting Jupyter-bridge: Error posting to Jupyter-bridge: Channel None:request contains unprocessed message
2024-02-14 13:51:31,681 [DEBUG] py4...: ǀǀǀǀǀǀǀǀǀǀǀǀǀǀ'cyrest_get' exception RequestException('Cannot find local or remote Cytoscape. Start Cytoscape and then proceed.')
2024-02-14 13:51:31,681 [DEBUG] py4...: ǀǀǀǀǀǀǀǀǀǀǀǀǀ'cytoscape_version_info' exception RequestException('Cannot find local or remote Cytoscape. Start Cytoscape and then proceed.')
2024-02-14 13:51:31,682 [DEBUG] py4...: ǀǀǀǀǀǀǀǀǀǀǀǀ'cytoscape_ping' exception RequestException('Cannot find local or remote Cytoscape. Start Cytoscape and then proceed.')
2024-02-14 13:51:32,099 [DEBUG] py4...: Error initially contacting Jupyter-bridge: Error posting to Jupyter-bridge: Channel None:request contains unprocessed message
2024-02-14 13:51:32,099 [DEBUG] py4...: ǀǀǀǀǀǀǀǀǀǀǀ'cyrest_get' exception RequestException('Cannot find local or remote Cytoscape. Start Cytoscape and then proceed.')
2024-02-14 13:51:32,101 [DEBUG] py4...: ǀǀǀǀǀǀǀǀǀǀ'cytoscape_version_info' exception RequestException('Cannot find local or remote Cytoscape. Start Cytoscape and then proceed.')
2024-02-14 13:51:32,101 [DEBUG] py4...: ǀǀǀǀǀǀǀǀǀ'cytoscape_ping' exception RequestException('Cannot find local or remote Cytoscape. Start Cytoscape and then proceed.')
2024-02-14 13:51:32,427 [DEBUG] py4...: Error initially contacting Jupyter-bridge: Error posting to Jupyter-bridge: Channel None:request contains unprocessed message
2024-02-14 13:51:32,429 [DEBUG] py4...: ǀǀǀǀǀǀǀǀ'cyrest_get' exception RequestException('Cannot find local or remote Cytoscape. Start Cytoscape and then proceed.')
2024-02-14 13:51:32,429 [DEBUG] py4...: ǀǀǀǀǀǀǀ'cytoscape_version_info' exception RequestException('Cannot find local or remote Cytoscape. Start Cytoscape and then proceed.')
2024-02-14 13:51:32,429 [DEBUG] py4...: ǀǀǀǀǀǀ'cytoscape_ping' exception RequestException('Cannot find local or remote Cytoscape. Start Cytoscape and then proceed.')
2024-02-14 13:51:32,470 [DEBUG] py4...: Attempting to connect to remote Cytoscape because of error HTTPConnectionPool(host='127.0.0.1', port=1234): Max retries exceeded with url: /v1 (Caused by NewConnectionError('<urllib3.connection.HTTPConnection object at 0x0000018A3A9B7880>: Failed to establish a new connection: [WinError 10061] 由于目标计算机积极拒绝，无法连接。'))
2024-02-14 13:51:32,470 [DEBUG] py4...: ǀǀǀǀǀHTTP GET(http://127.0.0.1:1234/v1)
2024-02-14 13:51:32,872 [DEBUG] py4...: Error initially contacting Jupyter-bridge: Error posting to Jupyter-bridge: Channel None:request contains unprocessed message
2024-02-14 13:51:32,872 [DEBUG] py4...: ǀǀǀǀǀ'cyrest_get' exception RequestException('Cannot find local or remote Cytoscape. Start Cytoscape and then proceed.')
2024-02-14 13:51:32,873 [DEBUG] py4...: ǀǀǀǀ'cytoscape_version_info' exception RequestException('Cannot find local or remote Cytoscape. Start Cytoscape and then proceed.')
2024-02-14 13:51:32,873 [DEBUG] py4...: ǀǀǀ'cytoscape_ping' exception RequestException('Cannot find local or remote Cytoscape. Start Cytoscape and then proceed.')
2024-02-14 13:51:33,747 [DEBUG] py4...: Error initially contacting Jupyter-bridge: Error posting to Jupyter-bridge: Channel None:request contains unprocessed message
2024-02-14 13:51:33,748 [DEBUG] py4...: ǀǀ'cyrest_get' exception RequestException('Cannot find local or remote Cytoscape. Start Cytoscape and then proceed.')
2024-02-14 13:51:33,748 [DEBUG] py4...: ǀ'cytoscape_version_info' exception RequestException('Cannot find local or remote Cytoscape. Start Cytoscape and then proceed.')
2024-02-14 13:51:33,748 [DEBUG] py4...: 'cytoscape_ping' exception RequestException('Cannot find local or remote Cytoscape. Start Cytoscape and then proceed.')
2024-02-14 13:51:33,748 [DEBUG] py4...: --------------------
2024-02-14 13:59:05,826 [DEBUG] py4...: Calling cytoscape_ping()
2024-02-14 13:59:05,826 [DEBUG] py4...: ǀCalling cytoscape_version_info(base_url='http://127.0.0.1:1234/v1')
2024-02-14 13:59:05,826 [DEBUG] py4...: ǀǀCalling cyrest_get('version', base_url='http://127.0.0.1:1234/v1')
2024-02-14 13:59:05,827 [DEBUG] py4...: Attempting to direct connect to Cytoscape on http://127.0.0.1:1234/v1
2024-02-14 13:59:06,026 [DEBUG] py4...: Detected py4cytoscape running on Cytoscape workstation
2024-02-14 13:59:06,026 [DEBUG] py4...: ǀǀHTTP GET(http://127.0.0.1:1234/v1/version)
2024-02-14 13:59:06,040 [DEBUG] py4...: ǀǀOK[200], content: {"apiVersion":"v1","cytoscapeVersion":"3.10.1"}
2024-02-14 13:59:06,041 [DEBUG] py4...: ǀǀReturning 'cyrest_get': {'apiVersion': 'v1', 'cytoscapeVersion': '3.10.1'}
2024-02-14 13:59:06,041 [DEBUG] py4...: ǀReturning 'cytoscape_version_info': {'apiVersion': 'v1', 'cytoscapeVersion': '3.10.1', 'automationAPIVersion': '1.9.0', 'py4cytoscapeVersion': '1.9.0'}
2024-02-14 13:59:06,041 [DEBUG] py4...: Returning 'cytoscape_ping': 'You are connected to Cytoscape!'
2024-02-14 13:59:06,041 [DEBUG] py4...: --------------------
2024-02-14 13:59:06,041 [DEBUG] py4...: Calling delete_all_networks()
2024-02-14 13:59:06,042 [DEBUG] py4...: ǀCalling cyrest_delete('networks', base_url='http://127.0.0.1:1234/v1', require_json=False)
2024-02-14 13:59:06,042 [DEBUG] py4...: ǀHTTP DELETE(http://127.0.0.1:1234/v1/networks)
2024-02-14 13:59:06,053 [DEBUG] py4...: ǀOK[200], content: 
2024-02-14 13:59:06,053 [DEBUG] py4...: ǀReturning 'cyrest_delete': ''
2024-02-14 13:59:06,054 [DEBUG] py4...: Returning 'delete_all_networks': ''
2024-02-14 13:59:06,054 [DEBUG] py4...: --------------------
2024-02-14 13:59:06,054 [DEBUG] py4...: Calling create_network_from_data_frames([{'data': {'id': 'a'}}, {'data': {'id': 'b'}}, {'data': {'id': 'c'}}], [{'data': {'source': 'a', 'target': 'b'}}, {'data': {'source': 'a', 'target': 'c'}}, {'data': {'source': 'b', 'target': 'c'}}], title='My Graph')
2024-02-14 13:59:06,054 [DEBUG] py4...: 'create_network_from_data_frames' exception TypeError('list indices must be integers or slices, not str')
2024-02-14 13:59:06,054 [DEBUG] py4...: --------------------
2024-02-14 14:11:21,010 [DEBUG] py4...: Calling cytoscape_ping()
2024-02-14 14:11:21,011 [DEBUG] py4...: ǀCalling cytoscape_version_info(base_url='http://127.0.0.1:1234/v1')
2024-02-14 14:11:21,011 [DEBUG] py4...: ǀǀCalling cyrest_get('version', base_url='http://127.0.0.1:1234/v1')
2024-02-14 14:11:21,011 [DEBUG] py4...: Attempting to direct connect to Cytoscape on http://127.0.0.1:1234/v1
2024-02-14 14:11:21,022 [DEBUG] py4...: Detected py4cytoscape running on Cytoscape workstation
2024-02-14 14:11:21,023 [DEBUG] py4...: ǀǀHTTP GET(http://127.0.0.1:1234/v1/version)
2024-02-14 14:11:21,032 [DEBUG] py4...: ǀǀOK[200], content: {"apiVersion":"v1","cytoscapeVersion":"3.10.1"}
2024-02-14 14:11:21,033 [DEBUG] py4...: ǀǀReturning 'cyrest_get': {'apiVersion': 'v1', 'cytoscapeVersion': '3.10.1'}
2024-02-14 14:11:21,033 [DEBUG] py4...: ǀReturning 'cytoscape_version_info': {'apiVersion': 'v1', 'cytoscapeVersion': '3.10.1', 'automationAPIVersion': '1.9.0', 'py4cytoscapeVersion': '1.9.0'}
2024-02-14 14:11:21,034 [DEBUG] py4...: Returning 'cytoscape_ping': 'You are connected to Cytoscape!'
2024-02-14 14:11:21,034 [DEBUG] py4...: --------------------
2024-02-14 14:11:21,034 [DEBUG] py4...: Calling delete_all_networks()
2024-02-14 14:11:21,035 [DEBUG] py4...: ǀCalling cyrest_delete('networks', base_url='http://127.0.0.1:1234/v1', require_json=False)
2024-02-14 14:11:21,035 [DEBUG] py4...: ǀHTTP DELETE(http://127.0.0.1:1234/v1/networks)
2024-02-14 14:11:21,043 [DEBUG] py4...: ǀOK[200], content: 
2024-02-14 14:11:21,044 [DEBUG] py4...: ǀReturning 'cyrest_delete': ''
2024-02-14 14:11:21,044 [DEBUG] py4...: Returning 'delete_all_networks': ''
2024-02-14 14:11:21,044 [DEBUG] py4...: --------------------
2024-02-14 14:11:21,044 [DEBUG] py4...: Calling create_network_from_data_frames([{'data': {'id': 'c'}}, {'data': {'id': 'a'}}, {'data': {'id': 'b'}}], [{'data': {'source': 'a', 'target': 'c'}}, {'data': {'source': 'a', 'target': 'b'}}, {'data': {'source': 'b', 'target': 'c'}}], title='My Graph')
2024-02-14 14:11:21,045 [DEBUG] py4...: 'create_network_from_data_frames' exception TypeError('list indices must be integers or slices, not str')
2024-02-14 14:11:21,045 [DEBUG] py4...: --------------------
